<mujoco model="FR5Cobot">
    <compiler angle="radian"/>
    <visual>
        <headlight ambient="0.5 0.5 0.5"/>
    </visual>
    <option timestep="0.0005" integrator="implicitfast" gravity="0 0 -9.81">
        <flag sensornoise="disable" contact="enable" energy="enable" gravity="enable"/>
    </option>
    <asset>
        <mesh name="base_link" file="meshes/base_link.STL"/>
        <mesh name="j1_Link" file="meshes/j1_Link.STL"/>
        <mesh name="j2_Link" file="meshes/j2_Link.STL"/>
        <mesh name="j3_Link" file="meshes/j3_Link.STL"/>
        <mesh name="j4_Link" file="meshes/j4_Link.STL"/>
        <mesh name="j5_Link" file="meshes/j5_Link.STL"/>
        <mesh name="j6_Link" file="meshes/j6_Link.STL"/>
    </asset>
    <worldbody>
        <!--  <light name="spotlight" mode="targetbodycom" target="j6_Link" pos="0 -1 2"/>-->
        <geom type="mesh" contype="0" conaffinity="0" group="1" density="0" rgba="0.89804 0.91765 0.92941 1"
              mesh="base_link"/>
        <geom type="mesh" rgba="0.89804 0.91765 0.92941 1" mesh="base_link"/>
        <body name="j1_Link">
            <inertial pos="5.0029e-07 -0.0040922 0.14629" quat="0.999588 0.0287044 7.54149e-06 -1.58789e-05"
                      mass="4.3771" diaginertia="0.010731 0.0104154 0.00817191"/>
            <joint name="j1" pos="0 0 0" axis="0 0 1" range="-3.0543 3.0543"/>
            <geom type="mesh" contype="0" conaffinity="0" group="1" density="0" rgba="0.89804 0.91765 0.92941 1"
                  mesh="j1_Link"/>
            <geom type="mesh" rgba="0.89804 0.91765 0.92941 1" mesh="j1_Link"/>
            <body name="j2_Link" pos="0 0 0.152" quat="0.707105 0.707108 0 0">
                <inertial pos="-0.2125 -5.7643e-09 0.1346" quat="0.5 0.5 0.5 0.5" mass="14.458"
                          diaginertia="0.4559 0.44974 0.028392"/>
                <joint name="j2" pos="0 0 0" axis="0 0 1" range="-4.6251 1.4835"/>
                <geom type="mesh" contype="0" conaffinity="0" group="1" density="0" rgba="0.89804 0.91765 0.92941 1"
                      mesh="j2_Link"/>
                <geom type="mesh" rgba="0.89804 0.91765 0.92941 1" mesh="j2_Link"/>
                <body name="j3_Link" pos="-0.425 0 0">
                    <inertial pos="-0.18793 -8.4503e-07 0.0066357" quat="0.510607 0.489172 0.489196 0.510568"
                              mass="7.6737" diaginertia="0.16971 0.168834 0.00821541"/>
                    <joint name="j3" pos="0 0 0" axis="0 0 1" range="-2.8274 2.8274"/>
                    <geom type="mesh" contype="0" conaffinity="0" group="1" density="0" rgba="0.89804 0.91765 0.92941 1"
                          mesh="j3_Link"/>
                    <geom type="mesh" rgba="0.89804 0.91765 0.92941 1" mesh="j3_Link"/>
                    <body name="j4_Link" pos="-0.39501 0 0">
                        <inertial pos="4.98e-07 -0.003754 0.097155" quat="0.736149 0.676819 -6.33095e-05 7.15237e-05"
                                  mass="1.6266" diaginertia="0.00216 0.00199337 0.00154233"/>
                        <joint name="j4" pos="0 0 0" axis="0 0 1" range="-4.6251 1.4835"/>
                        <geom type="mesh" contype="0" conaffinity="0" group="1" density="0"
                              rgba="0.89804 0.91765 0.92941 1" mesh="j4_Link"/>
                        <geom type="mesh" rgba="0.89804 0.91765 0.92941 1" mesh="j4_Link"/>
                        <body name="j5_Link" pos="0 0 0.1021" quat="0.707105 0.707108 0 0">
                            <inertial pos="-4.5588e-07 0.0038617 0.098257"
                                      quat="0.68712 0.726544 0.000128667 -0.000114125" mass="1.5812"
                                      diaginertia="0.0020612 0.00195889 0.00144611"/>
                            <joint name="j5" pos="0 0 0" axis="0 0 1" range="-3.0543 3.0543"/>
                            <geom type="mesh" contype="0" conaffinity="0" group="1" density="0"
                                  rgba="0.89804 0.91765 0.92941 1" mesh="j5_Link"/>
                            <geom type="mesh" rgba="0.89804 0.91765 0.92941 1" mesh="j5_Link"/>
                            <body name="j6_Link" pos="0 0 0.102" quat="0.707105 -0.707108 0 0">
                                <inertial pos="7.7496e-05 1.7751e-05 0.076122"
                                          quat="7.93213e-05 0.706804 0.00108234 0.707408" mass="0.52542"
                                          diaginertia="0.00041605 0.00027839 0.00027721"/>
                                <joint name="j6" pos="0 0 0" axis="0 0 1" range="-3.0543 3.0543"/>
                                <geom type="mesh" contype="0" conaffinity="0" group="1" density="0"
                                      rgba="0.89804 0.91765 0.92941 1" mesh="j6_Link"/>
                                <geom type="mesh" rgba="0.89804 0.91765 0.92941 1" mesh="j6_Link"/>
                            </body>
                        </body>
                    </body>
                </body>
            </body>
        </body>
    </worldbody>
    <actuator>
        <motor name="a1" ctrllimited="true" ctrlrange="-400.0 400.0" joint="j1"/>
        <motor name="a2" ctrllimited="true" ctrlrange="-400.0 400.0" joint="j2"/>
        <motor name="a3" ctrllimited="true" ctrlrange="-400.0 400.0" joint="j3"/>
        <motor name="a4" ctrllimited="true" ctrlrange="-400.0 400.0" joint="j4"/>
        <motor name="a5" ctrllimited="true" ctrlrange="-400.0 400.0" joint="j5"/>
        <motor name="a6" ctrllimited="true" ctrlrange="-400.0 400.0" joint="j6"/>
    </actuator>
</mujoco>
